{"trial_id": "2", "hyperparameters": {"space": [{"class_name": "Choice", "config": {"name": "optimizer", "default": "adam", "conditions": [], "values": ["adam", "sgd", "rmsprop", "adadelta"], "ordered": false}}], "values": {"optimizer": "rmsprop"}}, "metrics": {"metrics": {"accuracy": {"direction": "max", "observations": [{"value": [0.7736156582832336], "step": 3}]}, "loss": {"direction": "min", "observations": [{"value": [0.5286245346069336], "step": 3}]}, "val_accuracy": {"direction": "max", "observations": [{"value": [0.7727272510528564], "step": 3}]}, "val_loss": {"direction": "min", "observations": [{"value": [0.518812894821167], "step": 3}]}}}, "score": 0.7727272510528564, "best_step": 3, "status": "COMPLETED", "message": "Traceback (most recent call last):\n  File \"c:\\Users\\HP\\anaconda3\\Lib\\site-packages\\keras_tuner\\src\\engine\\base_tuner.py\", line 274, in _try_run_and_update_trial\n    self._run_and_update_trial(trial, *fit_args, **fit_kwargs)\n  File \"c:\\Users\\HP\\anaconda3\\Lib\\site-packages\\keras_tuner\\src\\engine\\base_tuner.py\", line 239, in _run_and_update_trial\n    results = self.run_trial(trial, *fit_args, **fit_kwargs)\n              ^^^^^^^^^^^^^^^^^^^^^^^^^^^^^^^^^^^^^^^^^^^^^^\n  File \"c:\\Users\\HP\\anaconda3\\Lib\\site-packages\\keras_tuner\\src\\engine\\tuner.py\", line 314, in run_trial\n    obj_value = self._build_and_fit_model(trial, *args, **copied_kwargs)\n                ^^^^^^^^^^^^^^^^^^^^^^^^^^^^^^^^^^^^^^^^^^^^^^^^^^^^^^^^\n  File \"c:\\Users\\HP\\anaconda3\\Lib\\site-packages\\keras_tuner\\src\\engine\\tuner.py\", line 233, in _build_and_fit_model\n    results = self.hypermodel.fit(hp, model, *args, **kwargs)\n              ^^^^^^^^^^^^^^^^^^^^^^^^^^^^^^^^^^^^^^^^^^^^^^^\n  File \"c:\\Users\\HP\\anaconda3\\Lib\\site-packages\\keras_tuner\\src\\engine\\hypermodel.py\", line 149, in fit\n    return model.fit(*args, **kwargs)\n           ^^^^^^^^^^^^^^^^^^^^^^^^^^\n  File \"c:\\Users\\HP\\anaconda3\\Lib\\site-packages\\keras\\src\\utils\\traceback_utils.py\", line 122, in error_handler\n    raise e.with_traceback(filtered_tb) from None\n  File \"c:\\Users\\HP\\anaconda3\\Lib\\site-packages\\keras\\src\\utils\\traceback_utils.py\", line 119, in error_handler\n    filtered_tb = _process_traceback_frames(e.__traceback__)\n                  ^^^^^^^^^^^^^^^^^^^^^^^^^^^^^^^^^^^^^^^^^^\nTypeError: TensorFlowTrainer.fit() got an unexpected keyword argument 'epocs'\n"}